Workbook
Name Abos_1: #REF!
Name Abos_1: #REF!
Name Abos_1: #REF!
Name Abos_10: #REF!
Name Abos_10: #REF!
Name Abos_10: #REF!
Name Abos_2: #REF!
Name Abos_2: #REF!
Name Abos_2: #REF!
Name Abos_3: #REF!
Name Abos_3: #REF!
Name Abos_3: #REF!
Name Abos_4: #REF!
Name Abos_4: #REF!
Name Abos_4: #REF!
Name Abos_5: #REF!
Name Abos_5: #REF!
Name Abos_5: #REF!
Name Abos_6: #REF!
Name Abos_6: #REF!
Name Abos_6: #REF!
Name Abos_7: #REF!
Name Abos_7: #REF!
Name Abos_7: #REF!
Name Abos_8: #REF!
Name Abos_8: #REF!
Name Abos_8: #REF!
Name Abos_9: #REF!
Name Abos_9: #REF!
Name Abos_9: #REF!
Name Aufwand: '[1]Drop Downs - Do not delete!'!$E$4:$E$7
Name Aufwand: '[1]Drop Downs - Do not delete!'!$E$4:$E$7
Name Aufwand: '[2]Drop Downs - Do not delete!'!$E$4:$E$7
Name Beratung_1: #REF!
Name Beratung_1: #REF!
Name Beratung_1: #REF!
Name Beratung_10: #REF!
Name Beratung_10: #REF!
Name Beratung_10: #REF!
Name Beratung_2: #REF!
Name Beratung_2: #REF!
Name Beratung_2: #REF!
Name Beratung_3: #REF!
Name Beratung_3: #REF!
Name Beratung_3: #REF!
Name Beratung_4: #REF!
Name Beratung_4: #REF!
Name Beratung_4: #REF!
Name Beratung_5: #REF!
Name Beratung_5: #REF!
Name Beratung_5: #REF!
Name Beratung_6: #REF!
Name Beratung_6: #REF!
Name Beratung_6: #REF!
Name Beratung_7: #REF!
Name Beratung_7: #REF!
Name Beratung_7: #REF!
Name Beratung_8: #REF!
Name Beratung_8: #REF!
Name Beratung_8: #REF!

Sheet Maturity assessment
G2: Rapid.AI - Indirect Procurement Assessment Tool - Questionnaire
C7: Category Levels | F7: Question Theme | G7: Assessment questionnaire | H7: Maturity Range | O7: Lever
B8: Q No. | C8: L1 | D8: L2 | E8: L3 | F8: Question Theme | G8: Questions | H8: Low (1) | I8: Little (2) | J8: Middle (3) | K8: High (4) | L8: Savings% (low) | M8: Savings% (high) | N8: Savings Opportunity | O8: Lever Description | P8: 4 Strategies | Q8: 16 Levers | R8: 64 Methods
A9: =_xlfn.CONCAT(C9,D9,O9) -> Office SuppliesNAConsolidate to max 3 suppliers for all office material spending | B9: 1 | C9: Office Supplies | D9: NA | G9: % Spend with the top 3 suppliers | H9: >60% | I9: >70% | J9: >80% | K9: >90% | L9: 0.01 | M9: 0.02 | N9: =_xlfn.CONCAT(TEXT(L9,"0.0%"),"-",TEXT(M9,"0.0%")) -> 1.0%-2.0% | O9: Consolidate to max 3 suppliers for all office material spending | P9: Leverage Competition Among Suppliers | Q9: Rationalize Supply Base | R9: Consolidate volume/reduce number of suppliers
A10: =_xlfn.CONCAT(C10,D10,O10) -> TravelAirIncluding budget airlines offers cost-effective options and leverages competition to reduce prices. | B10: 2 | C10: Travel | D10: Air | G10: Are budget airlines included in the portal? | H10: No or we do not have a travel portal | I10: No, but can be booked and expensed privately | J10: Yes, without its highlighting | K10: Yes, are displayed as preferred | L10: 0.005 | M10: 0.01 | N10: =_xlfn.CONCAT(TEXT(L10,"0.0%"),"-",TEXT(M10,"0.0%")) -> 0.5%-1.0% | O10: Including budget airlines offers cost-effective options and leverages competition to reduce prices. | P10: Leverage Competition Among Suppliers | Q10: Standardize Specifications | R10: Leverage competition (general)
A11: =_xlfn.CONCAT(C11,D11,O11) -> TravelRailOffering loyalty cards for rail travel reduces costs and enhances travel benefits through rewards. | B11: 3 | C11: Travel | D11: Rail | G11: Are employees able to apply for a loyalty card for the ground transport (rails)? | H11: Yes, anyone can submit a request | I11: After coordination with supervisors, an application can be submitted and approved | J11: Standard business case must be completed | K11: Anyone who regularly rides a train can submit an application | L11: 0.01 | M11: 0.02 | N11: =_xlfn.CONCAT(TEXT(L11,"0.0%"),"-",TEXT(M11,"0.0%")) -> 1.0%-2.0% | O11: Offering loyalty cards for rail travel reduces costs and enhances travel benefits through rewards. | P11: Seek Joint Advantage with Suppliers | Q11: Joint Process Improvement | R11: Improve loyalty programs/discounts
A12: =_xlfn.CONCAT(C12,D12,O12) -> FleetFuelDrive efficiently to save on fuel, reduce maintenance costs, and potentially earn insurance discounts. | B12: 4 | C12: Fleet | D12: Fuel | G12: Are employees incentivized to drive more efficient? | H12: No | I12: Employees are informed about the general policy of efficient driving | J12: Once employees receive a car they can conduct voluntary trainings | K12: Yes - training on efficienct driving is mandatory to take. Telemetic supports transparency | L12: 0.01 | M12: 0.02 | N12: =_xlfn.CONCAT(TEXT(L12,"0.0%"),"-",TEXT(M12,"0.0%")) -> 1.0%-2.0% | O12: Drive efficiently to save on fuel, reduce maintenance costs, and potentially earn insurance discounts. | P12: Change the Nature of Demand | Q12: Reduce Complexity | R12: Improve operational efficiency (e.g., fuel efficiency)
A13: =_xlfn.CONCAT(C13,D13,O13) -> FleetFuelImplement incentives for employees to reduce kilometers traveled, such as rewards for carpooling, using public transport, or biking to work. | B13: 5 | C13: Fleet | D13: Fuel | G13: Are employees incentivized to reduce km travelled? | H13: No | I13: Employees are informed about the general policy of not driving too many kms | J13: For business purposes employees are requested to reduce km allowance of travel | K13: Yes - avoid paying for privatly driven fuel (e.g. through telemetric solution), reduce km allowance of travel | L13: 0.01 | M13: 0.02 | N13: =_xlfn.CONCAT(TEXT(L13,"0.0%"),"-",TEXT(M13,"0.0%")) -> 1.0%-2.0% | O13: Implement incentives for employees to reduce kilometers traveled, such as rewards for carpooling, using public transport, or biking to work. | P13: Change the Nature of Demand | Q13: Reduce Consumption | R13: Incentivize reduced travel
A14: =_xlfn.CONCAT(C14,D14,O14) -> FleetFuelImplementing financial incentives, such as bonuses or matching contributions, encourages employees to save money by directly rewarding their savings efforts. | B14: 6 | C14: Fleet | D14: Fuel | G14: Are employees incentivized to tank at the cheapest station? | H14: No | I14: Employees are informed about fuel grade to purchase and card is limited to the relevant one | J14: In addition to the fuel grade, employees receive app in the beginning | K14: Yes, app for cheapest fuel station nearby is loaded on the phones and positive news coverage on the internal newsletter / incentivation for employees exist/ name & shame list | L14: 0.01 | M14: 0.02 | N14: =_xlfn.CONCAT(TEXT(L14,"0.0%"),"-",TEXT(M14,"0.0%")) -> 1.0%-2.0% | O14: Implementing financial incentives, such as bonuses or matching contributions, encourages employees to save money by directly rewarding their savings efforts. | P14: Change the Nature of Demand | Q14: Reduce Consumption | R14: Incentivize consumption reduction
A15: =_xlfn.CONCAT(C15,D15,O15) -> LegalNAIndicative hourly rates and experience levels allow performance-based project control and provide grounds for complaints if hours significantly exceed estimates. | B15: 7 | C15: Legal | D15: NA | G15: Are hourly rates and experience levels set and controlled for each contract? | H15: No | I15: Only for selected contracts | J15: For the majority of contracts | K15: Yes, completely | L15: 0.01 | M15: 0.02 | N15: =_xlfn.CONCAT(TEXT(L15,"0.0%"),"-",TEXT(M15,"0.0%")) -> 1.0%-2.0% | O15: Indicative hourly rates and experience levels allow performance-based project control and provide grounds for complaints if hours significantly exceed estimates. | P15: Manage Spend | Q15: Control Compliance | R15: Implement performance-based contracts/SLAs
A16: =_xlfn.CONCAT(C16,D16,O16) -> AuditNAIndicative hourly rates and experience levels allow performance-based project control and provide grounds for complaints if hours significantly exceed estimates. | B16: 8 | C16: Audit | D16: NA | G16: Are hourly rates and experience levels set and controlled for each contract? | H16: No | I16: Only for selected contracts | J16: For the majority of contracts | K16: Yes, completely | L16: 0.01 | M16: 0.02 | N16: =_xlfn.CONCAT(TEXT(L16,"0.0%"),"-",TEXT(M16,"0.0%")) -> 1.0%-2.0% | O16: Indicative hourly rates and experience levels allow performance-based project control and provide grounds for complaints if hours significantly exceed estimates. | P16: Manage Spend | Q16: Control Compliance | R16: Implement performance-based contracts/SLAs
A17: =_xlfn.CONCAT(C17,D17,O17) -> HRTrainingConsider training to be conducted internaly, enables to realize savings & build a training 100% to the need of the specific company & culture. | B17: 9 | C17: HR | D17: Training | G17: Are internal resources leverage to conduct trainings? | H17: No, external trainers are used | I17: There are few examples conducted, but they mainly did not work out. | J17: Yes, we have continuously been working on this strategy and overcome the initial downsides. | K17: Yes, around 60-70% of the trainings are conducted with internal experts | L17: 0.01 | M17: 0.02 | N17: =_xlfn.CONCAT(TEXT(L17,"0.0%"),"-",TEXT(M17,"0.0%")) -> 1.0%-2.0% | O17: Consider training to be conducted internaly, enables to realize savings & build a training 100% to the need of the specific company & culture. | P17: Change the Nature of Demand | Q17: Reduce Consumption | R17: Insourcing (for services)
A18: =_xlfn.CONCAT(C18,D18,O18) -> FleetWay of purchasingWithin a RFP ideally fix 1-2 OEMs, to ensure the received discounts are significant. | B18: 10 | C18: Fleet | D18: Way of purchasing | G18: Are preferential OEMs defined (car manufacturer) and pre-negotiated agreements exist? If yes, what is the % share of the top 3 OEMs? | H18: <50% | I18: 50-70% | J18: 70-90% | K18: >90% | L18: 0.01 | M18: 0.02 | N18: =_xlfn.CONCAT(TEXT(L18,"0.0%"),"-",TEXT(M18,"0.0%")) -> 1.0%-2.0% | O18: Within a RFP ideally fix 1-2 OEMs, to ensure the received discounts are significant. | P18: Leverage Competition Among Suppliers | Q18: Target Pricing & Cost modles | R18: Strategic supplier selection (focused)
A19: =_xlfn.CONCAT(C19,D19,O19) -> FleetPolicyImplementing programs to manage underutilized and oversized assets throughout their lifecycle ensures optimal usage and cost distribution. This approach helps in disposing of unnecessary assets, expanding their influence, and efficiently managing workloads with the use of third parties for peak times, resulting in significant cost savings | B19: 11 | C19: Fleet | D19: Policy | G19: Are there programs to reduce underutilized assets (e.g. pool cars) or oversized assets e.g. dispose, expand areas of influence, manage base workload and use 3rd parties for peak? | H19: No - we trust the people driving this topic take care of it | I19: Yes - there are policies existing but controlling is low | J19: Policies existing, controlling in certain countries not overarching | K19: Policies & tracking are regularly conducted, utilization is managed properly | L19: 0.01 | M19: 0.02 | N19: =_xlfn.CONCAT(TEXT(L19,"0.0%"),"-",TEXT(M19,"0.0%")) -> 1.0%-2.0% | O19: Implementing programs to manage underutilized and oversized assets throughout their lifecycle ensures optimal usage and cost distribution. This approach helps in disposing of unnecessary assets, expanding their influence, and efficiently managing workloads with the use of third parties for peak times, resulting in significant cost savings | P19: Change the Nature of Demand | Q19: Optimize Asset Utilization | R19: Optimize asset utilization/dispose of unused assets
A20: =_xlfn.CONCAT(C20,D20,O20) -> Office SuppliesNAUse white label where possible, typically this needs to be > 90% for office suppliers | B20: 12 | C20: Office Supplies | D20: NA | G20: Are white label (no-name brands) products focused? | H20: No | I20: They are offered | J20: They are preferred | K20: Only white lable products can be ordered | L20: 0.02 | M20: 0.04 | N20: =_xlfn.CONCAT(TEXT(L20,"0.0%"),"-",TEXT(M20,"0.0%")) -> 2.0%-4.0% | O20: Use white label where possible, typically this needs to be > 90% for office suppliers | P20: Leverage Competition Among Suppliers | Q20: Standardize Specifications | R20: Use white-label/private label products
... A39: =_xlfn.CONCAT(C39,D39,O39) -> ConsultingNASet-up framework contracts for different types of consulting work, allows to commercially tender and have the right rates in place. | B39: 31 | C39: Consulting | D39: NA | G39: Do you have a pre-qualification process for identifying and selecting qualified consulting providers with relevant experience and expertise in specific areas like compliance or risk management? | H39: No pre-qualification process | I39: Basic pre-qualification exists, but may not be consistently applied | J39: Standardized pre-qualification process ensures qualified consulting providers with relevant experience | K39: Rigorous pre-qualification process evaluates potential providers based on specific criteria aligned with project requirements and industry best practices | L39: 0.005 | M39: 0.01 | N39: =_xlfn.CONCAT(TEXT(L39,"0.0%"),"-",TEXT(M39,"0.0%")) -> 0.5%-1.0% | O39: Set-up framework contracts for different types of consulting work, allows to commercially tender and have the right rates in place. | P39: Leverage Competition Among Suppliers | Q39: Competitive Bidding | R39: Framework agreements
A40: =_xlfn.CONCAT(C40,D40,O40) -> TravelUber/ TaxiEstablishing agreements with taxi/Uber services ensures standardized rates and cost savings. | B40: 32 | C40: Travel | D40: Uber/ Taxi | G40: Do you have company agreements for taxis/ uber? | H40: No - employees can freely chose when they want to use what | K40: Yes- there are agreements with uber as well as taxi companies in place. The policy defines, that employees should primerily use Uber. | L40: 0.02 | M40: 0.04 | N40: =_xlfn.CONCAT(TEXT(L40,"0.0%"),"-",TEXT(M40,"0.0%")) -> 2.0%-4.0% | O40: Establishing agreements with taxi/Uber services ensures standardized rates and cost savings. | P40: Leverage Competition Among Suppliers | Q40: Competitive Bidding | R40: Negotiate framework agreements (travel)
A41: =_xlfn.CONCAT(C41,D41,O41) -> TravelHotelMaintaining an LRA rate card ensures standardized rates, fostering relationships and cost efficiencies. | B41: 33 | C41: Travel | D41: Hotel | G41: Do you have LRA rate card with Tier 1/Tier 2 hotel chains across top cities of travel? | H41: No LRA rate card | I41: LRA rate card with Tier 1 hotels only | J41: LRA rate card with Tier 2 hotels only | K41: LRA rate card with both Tier 1 and Tier 2 hotels | L41: 0.005 | M41: 0.01 | N41: =_xlfn.CONCAT(TEXT(L41,"0.0%"),"-",TEXT(M41,"0.0%")) -> 0.5%-1.0% | O41: Maintaining an LRA rate card ensures standardized rates, fostering relationships and cost efficiencies. | P41: Manage Spend | Q41: Control Compliance | R41: Standardize rate cards
A42: =_xlfn.CONCAT(C42,D42,O42) -> TravelCar RentalPartnering with preferred car rental providers ensures cost-effective rental options. | B42: 34 | C42: Travel | D42: Car Rental | G42: Do you have preferred partners with negotiated rates for Car rentals? | H42: No preferred partners | I42: Some preferred partners with minimal negotiations | J42: Preferred partners with standard negotiated rates | K42: Extensive preferred partners with comprehensive negotiated rates | L42: 0.01 | M42: 0.02 | N42: =_xlfn.CONCAT(TEXT(L42,"0.0%"),"-",TEXT(M42,"0.0%")) -> 1.0%-2.0% | O42: Partnering with preferred car rental providers ensures cost-effective rental options. | P42: Seek Joint Advantage with Suppliers | Q42: Joint Process Improvement | R42: Develop preferred supplier relationships (travel)
A43: =_xlfn.CONCAT(C43,D43,O43) -> ITSoftware development and maintenanceConsolidate contracts by developing small suppliers and establishing a preferred supplier pool for major development. Transition to fixed pricing with risk-sharing mechanisms and establish SLA guidelines to track compliance and shortcomings. | B43: 35 | C43: IT | D43: Software development and maintenance | G43: Do you have strategic supplier pools serving different needs? | H43: No | I43: - | J43: Only partially | K43: Yes | L43: 0.01 | M43: 0.02 | N43: =_xlfn.CONCAT(TEXT(L43,"0.0%"),"-",TEXT(M43,"0.0%")) -> 1.0%-2.0% | O43: Consolidate contracts by developing small suppliers and establishing a preferred supplier pool for major development. Transition to fixed pricing with risk-sharing mechanisms and establish SLA guidelines to track compliance and shortcomings. | P43: Leverage Competition Among Suppliers | Q43: Rationalize Supply Base | R43: Consolidate contracts & suppliers
A44: =_xlfn.CONCAT(C44,D44,O44) -> ITSoftware development and maintenanceLeveraging AI-based models can automate some parts of development and testing; thus reducing time and resource needs. This innovative approach minimizes manual tasks, cuts operational costs and boosts efficiency. | B44: 36 | C44: IT | D44: Software development and maintenance | G44: Do you leverage AI for development/ testing activities? | H44: Not at all | I44: Rarely | J44: Partially | K44: Fully | L44: 0.005 | M44: 0.01 | N44: =_xlfn.CONCAT(TEXT(L44,"0.0%"),"-",TEXT(M44,"0.0%")) -> 0.5%-1.0% | O44: Leveraging AI-based models can automate some parts of development and testing; thus reducing time and resource needs. This innovative approach minimizes manual tasks, cuts operational costs and boosts efficiency. | P44: Change the Nature of Demand | Q44: Reduce Complexity | R44: Automate processes (development/testing)
A45: =_xlfn.CONCAT(C45,D45,O45) -> ITIT helpdeskAutomating help desk inquiries with AI cuts support costs and frees up resources for complex issues. | B45: 37 | C45: IT | D45: IT helpdesk | G45: Do you leverage the full potential of AI to process help desk inquiries automatically? | H45: Not at all | I45: Rarely | J45: Partially | K45: Fully | L45: 0.015 | M45: 0.03 | N45: =_xlfn.CONCAT(TEXT(L45,"0.0%"),"-",TEXT(M45,"0.0%")) -> 1.5%-3.0% | O45: Automating help desk inquiries with AI cuts support costs and frees up resources for complex issues. | P45: Change the Nature of Demand | Q45: Reduce Complexity | R45: Automate processes (help desk)
A46: =_xlfn.CONCAT(C46,D46,O46) -> TravelPolicyPartnering with a travel agency streamlines bookings and leverages discounts, reducing travel costs. | B46: 38 | C46: Travel | D46: Policy | G46: Do you use Travel Agency for all your bookings? If not, what percentage of your bookings go through Client’s Travel Agency ? | H46: No travel agency used | I46: Less than 50% of bookings through the agency | J46: 50-70% of bookings through the agency | K46: More than 70% of bookings through the agency | L46: 0.01 | M46: 0.02 | N46: =_xlfn.CONCAT(TEXT(L46,"0.0%"),"-",TEXT(M46,"0.0%")) -> 1.0%-2.0% | O46: Partnering with a travel agency streamlines bookings and leverages discounts, reducing travel costs. | P46: Leverage Competition Among Suppliers | Q46: Consolidate Volume | R46: Consolidate travel agencies
A47: =_xlfn.CONCAT(C47,D47,O47) -> LogisticsLOG OceanUnbundled rates with categorized services for flexible cost management. | B47: 39 | C47: Logistics | D47: LOG Ocean | G47: Do you work with all-in rates or are these unbundled, e.g., comparing door-door with forwarder vs. port-port with self-managed pre-/on-carriage? | H47: All-in rates | I47: Mixed with more all-in rates | J47: Mixed with more unbundled rates | K47: Unbundled rates | L47: 0.01 | M47: 0.02 | N47: =_xlfn.CONCAT(TEXT(L47,"0.0%"),"-",TEXT(M47,"0.0%")) -> 1.0%-2.0% | O47: Unbundled rates with categorized services for flexible cost management. | P47: Manage Spend | Q47: Control Compliance | R47: Unbundle rates/services
A48: =_xlfn.CONCAT(C48,D48,O48) -> LogisticsRoad LogisticsStandard tenders focus on quotes and supplier margins, while expressive bidding also addresses systemic costs through volume discounts, bundle discounts, and alternative bids, leading to lower rates. | B48: 40 | C48: Logistics | D48: Road Logistics | G48: Do you work with all-in rates or are these unbundled, e.g., with separate fuel floater and surcharges? | H48: All-in rates | I48: Mixed with more all-in rates | J48: Mixed with more unbundled rates | K48: Unbundled rates | L48: 0.0025 | M48: 0.005 | N48: =_xlfn.CONCAT(TEXT(L48,"0.0%"),"-",TEXT(M48,"0.0%")) -> 0.3%-0.5% | O48: Standard tenders focus on quotes and supplier margins, while expressive bidding also addresses systemic costs through volume discounts, bundle discounts, and alternative bids, leading to lower rates. | P48: Leverage Competition Among Suppliers | Q48: Competitive Bidding | R48: Expressive bidding
A49: =_xlfn.CONCAT(C49,D49,O49) -> PackagingNACost-based price modeling is a process-oriented method for determining target prices. The basis for target prices are the individual process steps, to which reference values are applied. | B49: 41 | C49: Packaging | D49: NA | G49: Do your contracts include any sort of price adjustment mechanisms based on raw material indexes? | H49: No price adjustment clauses - fixed contract pricing only | I49: No automatic price adjustment clause, but regular (e.g. half-yearly) price negotiations | J49: Price adjustment clauses for the main categories in terms of spend | K49: Price adjustements for all contracts | L49: 0.025 | M49: 0.05 | N49: =_xlfn.CONCAT(TEXT(L49,"0.0%"),"-",TEXT(M49,"0.0%")) -> 2.5%-5.0% | O49: Cost-based price modeling is a process-oriented method for determining target prices. The basis for target prices are the individual process steps, to which reference values are applied. | P49: Leverage Competition Among Suppliers | Q49: Target Pricing & Cost Models | R49: Implement cost-based price modeling
A50: =_xlfn.CONCAT(C50,D50,O50) -> TravelAirDefining and enforcing flight class policies ensures cost-effective travel options. | B50: 42 | C50: Travel | D50: Air | G50: Flight: What classes can be booked? | H50: Not specified | I50: Business Class > 3 hours | J50: Business Class > 5 hours | K50: Only Economy Class | L50: 0.015 | M50: 0.03 | N50: =_xlfn.CONCAT(TEXT(L50,"0.0%"),"-",TEXT(M50,"0.0%")) -> 1.5%-3.0% | O50: Defining and enforcing flight class policies ensures cost-effective travel options. | P50: Manage Spend | Q50: Control Compliance | R50: Enforce travel policies (flight class)
A51: =_xlfn.CONCAT(C51,D51,O51) -> FleetPolicyLeasing duration can vary, offering flexibility in lease terms to suit different needs. | B51: 43 | C51: Fleet | D51: Policy | G51: For leasing cars with defined return date (closed-end lease cars): What is the typical leasing duration? | H51: Very diverse, depending who orders them | I51: Around 2 years as a standard | J51: Around 3 years as a standard | K51: 4-5 years, depending on the country (road conditions) | L51: 0.0025 | M51: 0.005 | N51: =_xlfn.CONCAT(TEXT(L51,"0.0%"),"-",TEXT(M51,"0.0%")) -> 0.3%-0.5% | O51: Leasing duration can vary, offering flexibility in lease terms to suit different needs. | P51: Change the Nature of Demand | Q51: Optimize Asset Utilization | R51: Flexible leasing terms
A52: =_xlfn.CONCAT(C52,D52,O52) -> MarketingPOS MaterialMove POS material to digital screens | B52: 44 | C52: Marketing | D52: POS Material | G52: For that % of current POS material that could be replaced with digital - what is the business case? | H52: Significant | I52: Good | J52: Low | K52: No business case | L52: 0.015 | M52: 0.03 | N52: =_xlfn.CONCAT(TEXT(L52,"0.0%"),"-",TEXT(M52,"0.0%")) -> 1.5%-3.0% | O52: Move POS material to digital screens | P52: Change the Nature of Demand | Q52: Reduce Consumption | R52: Substitute materials/processes (digital)
... A78: =_xlfn.CONCAT(C78,D78,O78) -> Temp LabourNAGlobal RFPs are conducted every 2-3 years, requesting additional savings ideas (e.g., reducing equal pay in Germany). | B78: 70 | C78: Temp Labour | D78: NA | G78: How is temp labour sourcing conducted? | H78: Every site/ BU sources their temp labour agencies individually | I78: BU bundle their volumes so that truly global volumes are put on the market | J78: Next to hourly rate and multiplier also other benefits are requested, e.g. free trainings, additional ideas to circumvent high payment | K78: Global RFPs are conducted and additional ideas for savings are requested (e.g. reduction of equal pay in Germany) | L78: 0.005 | M78: 0.01 | N78: =_xlfn.CONCAT(TEXT(L78,"0.0%"),"-",TEXT(M78,"0.0%")) -> 0.5%-1.0% | O78: Global RFPs are conducted every 2-3 years, requesting additional savings ideas (e.g., reducing equal pay in Germany). | P78: Leverage Competition Among Suppliers | Q78: Competitive Bidding | R78: Conduct global RFPs (regularly)
A79: =_xlfn.CONCAT(C79,D79,O79) -> HRTrainingStreamlining the training approval process and ensuring adherence to guidelines results in efficient procurement and cost savings | B79: 71 | C79: HR | D79: Training | G79: How is the approval process for training set-up? | H79: The employees does the training he wishes for | I79: The employee needs to discuss the trainings with his boss | K79: There is a rigorous approval process for trainings outside of prescribed catalogue and preferred partner network | L79: 0.015 | M79: 0.03 | N79: =_xlfn.CONCAT(TEXT(L79,"0.0%"),"-",TEXT(M79,"0.0%")) -> 1.5%-3.0% | O79: Streamlining the training approval process and ensuring adherence to guidelines results in efficient procurement and cost savings | P79: Manage Spend | Q79: Improve Process Efficiency | R79: Streamline approval processes
A80: =_xlfn.CONCAT(C80,D80,O80) -> ITEnd user/ Workplace HardwareStandardized hardware specifications / product variants. This enables more efficient sourcing & buying, along with better consistency and more streamlined support processes. | B80: 72 | C80: IT | D80: End user/ Workplace Hardware | G80: How is the specification of the HW defined? | H80: The specification is defined according to what the employees ask for. | I80: - | J80: Employee's needs are assessed and based on the relevant user group the specification is assigned to. | K80: Within a collaborative optimization the features are evaluated in monetary terms and decisions are based on them. | L80: 0.01 | M80: 0.02 | N80: =_xlfn.CONCAT(TEXT(L80,"0.0%"),"-",TEXT(M80,"0.0%")) -> 1.0%-2.0% | O80: Standardized hardware specifications / product variants. This enables more efficient sourcing & buying, along with better consistency and more streamlined support processes. | P80: Change the Nature of Demand | Q80: Optimize Specifications | R80: Standardize hardware specifications
A81: =_xlfn.CONCAT(C81,D81,O81) -> Facility ManagementNAEstablish a central Facility Management organization for easier service provider monitoring, increased transparency, and better control over categories and services. | B81: 73 | C81: Facility Management | D81: NA | G81: How is your facility management organized? | H81: Not organized | I81: Local | J81: Regional | K81: Central | L81: 0.005 | M81: 0.01 | N81: =_xlfn.CONCAT(TEXT(L81,"0.0%"),"-",TEXT(M81,"0.0%")) -> 0.5%-1.0% | O81: Establish a central Facility Management organization for easier service provider monitoring, increased transparency, and better control over categories and services. | P81: Manage Spend | Q81: Improve Process Efficiency | R81: Centralize FM organization
A82: =_xlfn.CONCAT(C82,D82,O82) -> TravelTravel Management AgencyConsolidating travel agencies leverages volume bundling, reducing costs through economies of scale. | B82: 74 | C82: Travel | D82: Travel Management Agency | G82: How many active travel agencies are you working with? | H82: Every country has its own | I82: 30% spend bundled to one agency | J82: 60% spend bundled to one agency | K82: Close to 100% bundled to one agency | L82: 0.02 | M82: 0.04 | N82: =_xlfn.CONCAT(TEXT(L82,"0.0%"),"-",TEXT(M82,"0.0%")) -> 2.0%-4.0% | O82: Consolidating travel agencies leverages volume bundling, reducing costs through economies of scale. | P82: Leverage Competition Among Suppliers | Q82: Consolidate Volume | R82: Consolidate travel agencies
A83: =_xlfn.CONCAT(C83,D83,O83) -> LogisticsRoad LogisticsIn the current market, carriers can cherry-pick customers and loads, so it's crucial to become a shipper of choice by enhancing warehouse infrastructure and improving communication with carriers. | B83: 75 | C83: Logistics | D83: Road Logistics | G83: How many carriers did participate in the last tender? | H83: <5 | I83: 5-10 | J83: 10-25 | K83: >25 | L83: 0.0025 | M83: 0.005 | N83: =_xlfn.CONCAT(TEXT(L83,"0.0%"),"-",TEXT(M83,"0.0%")) -> 0.3%-0.5% | O83: In the current market, carriers can cherry-pick customers and loads, so it's crucial to become a shipper of choice by enhancing warehouse infrastructure and improving communication with carriers. | P83: Seek Joint Advantage with Suppliers | Q83: Joint Capacity & Planning | R83: Become shipper of choice
A84: =_xlfn.CONCAT(C84,D84,O84) -> LogisticsLOG OceanLeveraging carrier participation for competitive ocean freight rates. | B84: 76 | C84: Logistics | D84: LOG Ocean | G84: How many carriers did participate in the last tender? | H84: <5 | I84: 5-10 | J84: 10-15 | K84: >15 | L84: 0.005 | M84: 0.01 | N84: =_xlfn.CONCAT(TEXT(L84,"0.0%"),"-",TEXT(M84,"0.0%")) -> 0.5%-1.0% | O84: Leveraging carrier participation for competitive ocean freight rates. | P84: Leverage Competition Among Suppliers | Q84: Competitive Bidding | R84: Leverage carrier participation
A85: =_xlfn.CONCAT(C85,D85,O85) -> LogisticsRoad LogisticsTransportation is often managed by a long-term partner with premium rates, but regularly seeking multiple quotes for large volumes helps identify alternatives and true market rates. | B85: 77 | C85: Logistics | D85: Road Logistics | G85: How many carriers do you have on your contact longlist? | H85: >50 | I85: 25-50 | J85: 25-10 | K85: <10 | L85: 0.0025 | M85: 0.005 | N85: =_xlfn.CONCAT(TEXT(L85,"0.0%"),"-",TEXT(M85,"0.0%")) -> 0.3%-0.5% | O85: Transportation is often managed by a long-term partner with premium rates, but regularly seeking multiple quotes for large volumes helps identify alternatives and true market rates. | P85: Leverage Competition Among Suppliers | Q85: Competitive Bidding | R85: Benchmark and seek multiple quotes
A86: =_xlfn.CONCAT(C86,D86,O86) -> LogisticsLOG OceanOptimize carrier network by consolidating suppliers into specific categories. | B86: 78 | C86: Logistics | D86: LOG Ocean | G86: How many carriers do you have on your contact longlist? | H86: <10 | I86: 10-20 | J86: 20-30 | K86: >30 | L86: 0.005 | M86: 0.01 | N86: =_xlfn.CONCAT(TEXT(L86,"0.0%"),"-",TEXT(M86,"0.0%")) -> 0.5%-1.0% | O86: Optimize carrier network by consolidating suppliers into specific categories. | P86: Leverage Competition Among Suppliers | Q86: Rationalize Supply Base | R86: Optimize carrier network/consolidate suppliers
A87: =_xlfn.CONCAT(C87,D87,O87) -> Facility ManagementNATrack and monitor a critical number of KPIs for effective governance; avoid too few or too many (over 15) KPIs to manage monitoring efforts efficiently. | B87: 79 | C87: Facility Management | D87: NA | G87: How many KPIs do you have in place to monitor the performance of the facility management providers? | H87: No KPIs defined | I87: >15 | J87: 10-15 | K87: 5-10 | L87: 0.01 | M87: 0.02 | N87: =_xlfn.CONCAT(TEXT(L87,"0.0%"),"-",TEXT(M87,"0.0%")) -> 1.0%-2.0% | O87: Track and monitor a critical number of KPIs for effective governance; avoid too few or too many (over 15) KPIs to manage monitoring efforts efficiently. | P87: Manage Spend | Q87: Control Compliance | R87: Implement effective KPI monitoring
A88: =_xlfn.CONCAT(C88,D88,O88) -> TravelPolicyEvaluating travel flexibility balances cost control with business needs, optimizing travel spend. | B88: 80 | C88: Travel | D88: Policy | G88: How much flexibility does your department require when travelling? | H88: Complete flexibility | I88: Limited flexibility within predefined policies | J88: Strict adherence to policies | K88: Case-by-case flexibility based on approval | L88: 0.01 | M88: 0.02 | N88: =_xlfn.CONCAT(TEXT(L88,"0.0%"),"-",TEXT(M88,"0.0%")) -> 1.0%-2.0% | O88: Evaluating travel flexibility balances cost control with business needs, optimizing travel spend. | P88: Change the Nature of Demand | Q88: Optimize Service Levels | R88: Evaluate travel flexibility
...

Sheet V1
J1: Hypotheses - Proof points
A2: L1 | B2: L2 | C2: Region | D2: Hypotheses (Value drivers) / Questions | E2: Standard initiative description | F2: 64 methods | G2: 16 Levers | H2: 4 Strategies | J2: Avg. spend / supplier | K2: Category spend vs. revenue | L2: Supplier fragmentation for botton 20% spend | M2: Price variations | N2: Regional fragmentation | O2: Single source / monopolistic traits | P2: Supplier concentration for top 80% spend | Q2: Low cost country options | R2: Supplier intel | S2: Market price trends
A3: Plant-based | B3: Grains | D3: Are you leveraging by-product opportunities, such as combo buying (e.g., bran and wheat flour), to reduce costs? | E3: Maximize resource utilization by ensuring all parts of the product (e.g., fish) are used effectively, often through combo buying strategies. | G3: Volume bundling | H3: Leverage competition among suppliers | J3: 1. Calculate 'category spend / # of unique suppliers' 2. If value < benchmark, then this category is relatively fragmented compare to peers i.e., this proof point confirms that there is value in reducing supplier fragmentation | L3: In case this proof-point shows high fragmentation in bottom 20% spend, then augment the initiative by describing the extent of fragmentation e.g., >90% supplier make up the bottom 20% spend
A4: Plant-based | B4: Grains | D4: Have you reviewed pack sizes or explored bulk purchasing options to optimize costs and streamline the supply chain? | E4: Improve material flow management to reduce waste, enhance efficiency, and lower costs across the supply chain. | G4: Volume bundling | H4: Leverage competition among suppliers
A5: Plant-based | B5: Grains | D5: How often do you conduct footprint optimization studies to enhance efficiency in grains sourcing and distribution? | E5: Improve material flow management to reduce waste, enhance efficiency, and lower costs across the supply chain. | G5: Volume bundling | H5: Leverage competition among suppliers | N5: If a large number of countries/regions contribute to a high percentage of total spend (e.g., >80%), then there can be potential to optimize the supply base. Callout such examples of locations that can be consolidated, while describing initiatives | Q5: Augment the initiative by mentioning incumbent low cost countries. If available, add country-specific differences in RM and freight costs - this shuld be directional and not numeric. Using market data, also highlight the risk associated with these countries
A6: Plant-based | B6: Grains | D6: Have you considered or implemented swapping specialty products for more cost-effective alternatives in your grains procurement? | E6: Substitute premium materials with lower-grade alternatives that meet functional requirements while reducing costs. | G6: Re-specification | H6: Seek joint advantage with supplier
A7: Plant-based | B7: Grains | D7: How often do you evaluate and adjust the inclusion levels of specialty products to incorporate standard products without compromising product quality? | E7: Optimize recipes by lowering expensive ingredient levels and replacing them with cost-effective substitutes. | G7: Re-specification | H7: Change nature of demand
A8: All | B8: All | D8: Geographic Sourcing Optimization for Cost Reduction - If significant spend for common goods/services occurs with suppliers located in high-cost regions, when similar quality suppliers exist in lower-cost regions (requires external data on regional cost indices), then a sourcing shift could yield savings due to reduced transportation and tarriffs | E8: Move spend to lower cost countries, starting with incumbents with a presence in low cost countries | G8: Global Sourcing | H8: Manage spend | Q8: Contextualize the initiative by mentioning high cost and low cost countries - ensure to callout most relevant regions/countries; along with market-data based suggestions on alternatives
A9: Plant-based | B9: Grains | D9: How often do you engage in open book costing with your suppliers to enhance transparency in pricing? | E9: Explore open book costing with top suppliers (top 80% spend) within the grains category | G9: Supplier pricing review | H9: Change nature of demand | P9: In case supplier concentration (top 80% spend) is high, then callout the top suppliers who could be targeted for this initiative.
A10: Plant-based | B10: Grains | D10: Are you actively considering suppliers located outside a specific geographic range (e.g., 500 km) to enhance competition and reduce costs? | E10: Foster supplier competition to secure competitive pricing and supply flexibility through strategies like supplier rotation and e-auctions. | G10: Supplier pricing review | H10: Change nature of demand
A11: Plant-based | B11: Grains | D11: Do you currently bundle purchases of related grains or ingredients (e.g., coarse and fine grains) to achieve volume discounts? | E11: Leverage bulk purchasing agreements and combo buying strategies to achieve economies of scale and cost efficiency. | G11: Volume bundling | H11: Change nature of demand | J11: 1. Calculate 'category spend / # of unique suppliers' 2. If value < benchmark, then this category is relatively fragmented compare to peers i.e., this proof point confirms that there is value in reducing supplier fragmentation
A12: Plant-based | B12: Grains | D12: Do you allow suppliers to make financial hedges on your behalf to manage cost volatility? If yes, how is this monitored? | E12: For imported grain supplies, empower suppliers to hedge financial risks e.g., taking a position in the futures or options market, informed by market forecasts | G12: Risk management | H12: Leverage competition among suppliers
A13: All | B13: All | D13: Is contract compliance tracked? If a high percentage of spend within a category is not linked to any discernible contract ID or occurs with suppliers outside a recognized 'preferred' list, then there's a risk of non-compliance and uncontrolled spend | E13: Track contract compliance e.g., are you buying from the right suppliers and at the right / negotiated prices? | G13: Compliance Management | H13: Manage spend
A14: All | B14: All | D14: Payment Term Optimization Potential - Working Capital Opportunity -- If the average payment cycle (from invoice date to payment date) for a significant portion of invoices is consistently very short (e.g., <20 days when 30-60 days is common), and there is no evidence of early payment discounts being captured, then there's an opportunity to optimize working capital | E14: Evaluate typical industry trends and negotiate higher payment days to unlock working capital. Focus on top suppliers (top 80% spend). | G14: Intelligent Deal Structure | H14: Leverage competition among suppliers

Sheet Sheet2
A1: L2 | B1: (All)
A3: Row Labels
A4: Risk
A5: Re-specification
A6: To what degree is the spend across suppliers concentrated within this category?
A7: To what degree is there a risk to prices for the major supply gerographies for this category?
A8: What is the average (weight avg) financial risk profile of top suppliers? (suppliers covering top 80% spend)
A9: What is the average (weighted avg) regional / geopoltical risk score across top suppliers?
A10: Value
A11: Cost Partnership
A12: How does your supplier strategy guide decisions on where to focus R&D for improving cost efficiency or innovation in vegetable oils?
A13: Globalization
A14: Have you considered shifting sourcing origins to take advantage of cost or availability benefits? If so, what challenges have you faced?
... A35: Grand Total

Sheet 1_Value & risk levers
H2: Rapid.AI - Indirect Procurement Assessment Tool - Questionnaire - CIRP directs
D7: Category Levels | G7: Question Theme | H7: Assessment questionnaire | I7: Maturity Range | P7: Lever
B8: Q No. | C8: Lever / initiative type | D8: L1 | E8: L2 | F8: L3 | G8: Question Theme | H8: Questions | I8: Low (1) | J8: Little (2) | K8: Middle (3) | L8: High (4) | M8: Savings% (low) | N8: Savings% (high) | O8: Addressability | P8: Lever Description | Q8: 4 Strategies | R8: 16 Levers | S8: 64 Methods | T8: Score (1-4) | U8: t
C9: Value | D9: Plant-based | E9: Vegetable Oils | G9: Value | H9: Are financial instruments, such as hedging or long-term contracts, used to manage risks in vegetable oil procurement? | I9: Not utilized | J9: Basic usage for high-risk categories | K9: Regularly employed for risk management | L9: Strategically implemented with advanced forecasting | M9: 0.02 | N9: 0.05 | O9: 0.8 | P9: Broader supplier strategy to determine where to focus R&D. Lock part of the price (mark-up) and follow market-based pricing. Use financial instruments to hedge risks. Lock volumes early in the season. | R9: Risk management | T9: 2 | U9: =VLOOKUP(H9,'2_Methodology (Value)'!$H$3:$H$1048576,1,FALSE) -> Are financial instruments, such as hedging or long-term contracts, used to manage risks in vegetable oil procurement?
C10: Value | D10: Plant-based | E10: Vegetable Oils | G10: Value | H10: Do you approve / qualify multiple suppliers for specialty products to hedge against significant risks in the supply chain? | I10: Single sourced / reliance on a single supplier forspecialty products | J10: Largely monopolistic for most specialty products e.g., a pool of 2-3 qualified / approved suppliers to choose from | K10: Multiple qualified suppliers / preferred supplier list for majoe specialty products | L10: Diversified sourcing options maintained for all specialties | M10: 0.02 | N10: 0.05 | O10: 0.8 | P10: Qualify and approve multiple suppliers for specialty products to hedge against supply risks. Activate these suppliers in case of regional supply chain issues. | R10: Risk management | T10: 2 | U10: =VLOOKUP(H10,'2_Methodology (Value)'!$H$3:$H$1048576,1,FALSE) -> Do you approve / qualify multiple suppliers for specialty products to hedge against significant risks in the supply chain?
C11: Value | D11: Plant-based | E11: Vegetable Oils | G11: Value | H11: To what extent do you use should cost models to challenge and negotiate supplier pricing? | I11: Rarely used | J11: Occasionally applied in negotiations, not a structured / defined approach for category managers to follow | K11: Regular practice for most vegetable oils, but requires manual calculations / manual updates | L11: Advanced/ automated modeling integrated into procurement tools | M11: 0.02 | N11: 0.05 | O11: 0.8 | P11: Challenge suppliers with should-cost models to ensure cost-effectiveness. Incoporate data automation to auto calculate should-cost based prices | R11: Target pricing | T11: 1 | U11: =VLOOKUP(H11,'2_Methodology (Value)'!$H$3:$H$1048576,1,FALSE) -> To what extent do you use should cost models to challenge and negotiate supplier pricing?
C12: Value | D12: Plant-based | E12: Vegetable Oils | G12: Value | H12: To what extent have you explored bundling of volumes across different types of vegetable oils to maximize economies of scale? | I12: Not practiced / not explored so far | J12: Ad-hoc initiatives to bundle volume across suppliers | K12: Suppliers are evaluated for their product coverage at the time of sourcing | L12: Comprehensive bundling strategy across all vegetable oils - following an optimization approach to identify the right volume mix across suppliers and SKUs | M12: 0.02 | N12: 0.05 | O12: 0.8 | P12: Bundle volumes across SKUs to achieve savings derived from better economies of scale. Focus on high-spend SKUs that are purchased from multiple suppliers. Potentially consolidate SKUs within the tail. | R12: Volume bundling | T12: 3 | U12: =VLOOKUP(H12,'2_Methodology (Value)'!$H$3:$H$1048576,1,FALSE) -> To what extent have you explored bundling of volumes across different types of vegetable oils to maximize economies of scale?
C13: Value | D13: Plant-based | E13: Vegetable Oils | G13: Value | H13: Have you undertaken specification rationalization to enable volume bundling and reduce sourcing complexity? | I13: Not undertaken | J13: Initial stages of exploration, requires more work | K13: Ad-hoc but frequent rationalization initiatives | L13: Fully optimized methodology to review cost and simplicity periodically | M13: 0.02 | N13: 0.03 | O13: 0.8 | P13: Rationalize specifications to allow for volume bundling and simplification. | R13: Re-specification | T13: 4 | U13: =VLOOKUP(H13,'2_Methodology (Value)'!$H$3:$H$1048576,1,FALSE) -> Have you undertaken specification rationalization to enable volume bundling and reduce sourcing complexity?
C14: Value | D14: Plant-based | E14: Vegetable Oils | G14: Value | H14: Have you considered shifting sourcing origins to take advantage of cost or availability benefits? If so, what challenges have you faced? | I14: Not considered | J14: Limited exploration of alternative origins | K14: Regularly sourcing from diverse origins | L14: Fully optimized global sourcing with risk mitigation plans | M14: 0.02 | N14: 0.03 | O14: 0.8 | P14: Switch origins to adjust to market dynamics and cost advantages. | R14: Globalization | T14: 1 | U14: =VLOOKUP(H14,'2_Methodology (Value)'!$H$3:$H$1048576,1,FALSE) -> Have you considered shifting sourcing origins to take advantage of cost or availability benefits? If so, what challenges have you faced?
C15: Value | D15: Plant-based | E15: Vegetable Oils | G15: Value | H15: Do you review pack sizes and explore delivery options in bulk or flexi tanks to streamline supply chain operations and reduce costs? | I15: No review conducted | J15: Limited trials for bulk options | K15: Regular assessments to optimize packaging | L15: Fully optimized with advanced logistics planning | M15: 0.02 | N15: 0.03 | O15: 0.8 | P15: Review pack sizes and set up delivery in bulk/flexi-tanks for efficiency. | R15: Re-specification | T15: 1 | U15: =VLOOKUP(H15,'2_Methodology (Value)'!$H$3:$H$1048576,1,FALSE) -> Do you review pack sizes and explore delivery options in bulk or flexi tanks to streamline supply chain operations and reduce costs?
C16: Risk | D16: Plant-based | E16: Vegetable Oils | G16: Risk | H16: To what degree is the spend across suppliers concentrated within this category? | I16: >80% of spend is with a single supplier | J16: Top 2 suppliers cover >80% of spend | K16: Top 3-4 suppliers cover >80% of spend | L16: 5 or more suppliers contribute to the top 80% spend | R16: Re-specification | T16: 4
C17: Risk | D17: Plant-based | E17: Vegetable Oils | G17: Risk | H17: What is the average (weight avg) financial risk profile of top suppliers? (suppliers covering top 80% spend) | I17: >75% spend is linked to high risk suppliers (risk score <30) | J17: 50-75% spend is linked to high risk suppliers (risk score <30) | K17: 30-50% spend is linked to high risk suppliers (risk score <30) | L17: <30% spend is linked to high risk suppliers (risk score <30) | R17: Re-specification | T17: 2
C18: Risk | D18: Plant-based | E18: Vegetable Oils | G18: Risk | H18: What is the average (weighted avg) regional / geopoltical risk score across top suppliers? | I18: >75% spend is linked to high risk suppliers (risk score >=DB5) | J18: 50-75% spend is linked to high risk suppliers (risk score >=DB5) | K18: 30-50% spend is linked to high risk suppliers (risk score >=DB5) | L18: <30% spend is linked to high risk suppliers (risk score >=DB5) | R18: Re-specification | T18: 3
C19: Risk | D19: Plant-based | E19: Vegetable Oils | G19: Risk | H19: To what degree is there a risk to prices for the major supply gerographies for this category? | I19: >75% spend is linked to regions witnessing price inflation due to cost driver inflation, tariffs, demand / supply imbalance etc. | J19: 50-75% spend is linked to regions witnessing price inflation due to cost driver inflation, tariffs, demand / supply imbalance etc. | K19: 30-50% spend is linked to regions witnessing price inflation due to cost driver inflation, tariffs, demand / supply imbalance etc. | L19: <30% spend is linked to regions witnessing price inflation due to cost driver inflation, tariffs, demand / supply imbalance etc. | R19: Re-specification | T19: 2
B20: 1 | C20: Value | D20: Plant-based | E20: Vegetable Oils | G20: Value | H20: How does your supplier strategy guide decisions on where to focus R&D for improving cost efficiency or innovation in vegetable oils? | I20: No connection between supplier strategy and R&D | J20: Occasional collaboration for innovation | K20: Regular input from suppliers to guide R&D | L20: Integrated partnerships driving co-developed innovations | M20: 0.02 | N20: 0.05 | O20: 0.8 | P20: Broader supplier strategy to determine where to focus R&D. Lock part of the price (mark-up) and follow market-based pricing. Use financial instruments to hedge risks. Lock volumes early in the season. | R20: Cost Partnership | T20: 2 | U20: =VLOOKUP(H20,'2_Methodology (Value)'!$H$3:$H$1048576,1,FALSE) -> #N/A
B21: 2 | C21: Value | D21: Plant-based | E21: Vegetable Oils | G21: Value | H21: Do you lock part of the price (e.g., mark-up) and allow commodity pricing to follow market trends? If so, how do you monitor its effectiveness? | I21: Not practiced | J21: Commodity indices are linked to pricing, no defined methodology to track and review this | K21: Commodity indices are linked to prices, and category managers / buyers calculate the market impact manually as per defined review periods | L21: Automated index-based price calculations by SKU, plant, supplier etc. | M21: 0.02 | N21: 0.05 | O21: 0.8 | P21: Broader supplier strategy to determine where to focus R&D. Lock part of the price (mark-up) and follow market-based pricing. Use financial instruments to hedge risks. Lock volumes early in the season. | R21: Supplier pricing review | T21: 3 | U21: =VLOOKUP(H21,'2_Methodology (Value)'!$H$3:$H$1048576,1,FALSE) -> #N/A
B22: 4 | C22: Value | D22: Plant-based | E22: Vegetable Oils | G22: Value | H22: How early in the season do you lock in volumes to ensure supply stability and pricing predictability? | I22: Not practiced | L22: We typically aim to lock-in prices early in the season, based on crop reports, yield estimates etc | M22: 0.02 | N22: 0.05 | O22: 0.8 | P22: Broader supplier strategy to determine where to focus R&D. Lock part of the price (mark-up) and follow market-based pricing. Use financial instruments to hedge risks. Lock volumes early in the season. | R22: Risk management | U22: =VLOOKUP(H22,'2_Methodology (Value)'!$H$3:$H$1048576,1,FALSE) -> #N/A
B23: 8 | C23: Value | D23: Plant-based | E23: Vegetable Oils | G23: Value | H23: Have you explored switching to the cheapest alternatives for vegetable oils without compromising product quality or functionality? | I23: Not explored | J23: Limited trials conducted | K23: Regular evaluation and switching | L23: Embedded in procurement and formulation strategies | M23: 0.02 | N23: 0.03 | O23: 0.8 | P23: Switch to the cheapest alternative materials while maintaining functionality. | R23: Re-specification | T23: 1 | U23: =VLOOKUP(H23,'2_Methodology (Value)'!$H$3:$H$1048576,1,FALSE) -> #N/A
B24: 9 | C24: Value | D24: Plant-based | E24: Vegetable Oils | G24: Value | H24: To what extent have you explored implementing blending of specialty products with commodities to reduce costs or optimize product formulations? | I24: Not explored / implemented | J24: Initial stages of exploration, requires more work | K24: Ad-hoc examples of formulation adjustments for expensive specialty products | L24: We have a periodic governance / review mechanism to evaluate the inclusion of specialty products | M24: 0.02 | N24: 0.03 | O24: 0.8 | P24: Blend specialty products and focus on expensive specialty products for optimization. | R24: Re-specification | T24: 2 | U24: =VLOOKUP(H24,'2_Methodology (Value)'!$H$3:$H$1048576,1,FALSE) -> #N/A
B25: 10 | C25: Value | D25: Plant-based | E25: Vegetable Oils | G25: Value | H25: Are you leveraging specific strategies for managing expensive specialty products? If so, how effective have they been? | I25: No specific strategies | J25: Basic cost-saving measures | K25: Effective strategies for major specialties | L25: Advanced strategies with measurable cost reductions | M25: 0.02 | N25: 0.03 | O25: 0.8 | P25: Blend specialty products and focus on expensive specialty products for optimization. | T25: 3 | U25: =VLOOKUP(H25,'2_Methodology (Value)'!$H$3:$H$1048576,1,FALSE) -> #N/A
B26: 12 | C26: Value | D26: Plant-based | E26: Vegetable Oils | G26: Value | H26: How often do you identify opportunities to simplify your portfolio of vegetable oils to enhance procurement efficiency? | I26: Rarely addressed | J26: Occasional portfolio reviews | K26: Regular reviews to identify simplification | L26: Continuously optimized portfolio management | M26: 0.02 | N26: 0.03 | O26: 0.8 | P26: Simplify the portfolio where possible to reduce complexity and costs. | R26: Technical data mining | U26: =VLOOKUP(H26,'2_Methodology (Value)'!$H$3:$H$1048576,1,FALSE) -> #N/A
B27: 13 | C27: Value | D27: Plant-based | E27: Vegetable Oils | G27: Value | H27: To what extent do you maintain flexible formulations / recipe flexibility to accommodate alternative or varied specifications of vegetable oils? | I27: Not maintained | J27: Ad-hoc / one-off design and testing of new formulations, based on specific projects / initiatives | K27: We maintain a list of potential formulations, however the should-costs for these are not transparent / not maintained periodically | L27: We maintain a list of formulations, updated with market prices regularly to identify relative cost benefits | M27: 0.02 | N27: 0.03 | O27: 0.8 | P27: Enable recipe flexibility to expand sourcing options. | R27: Re-specification | T27: 3 | U27: =VLOOKUP(H27,'2_Methodology (Value)'!$H$3:$H$1048576,1,FALSE) -> #N/A

Sheet Sheet5

Sheet 2_Methodology (Value)
M1: Maturity Range | T1: Risk profile calc. | W1: Category-level savings / addressability | AK1: Directional initiative-level %es | BK1: Mapping for value initiative details view | BR1: Mapping for value initiative details view
A2: Initiative ID | B2: Industry group | C2: Industry segment | D2: L1 | E2: L2 | F2: Region | G2: Hypotheses type | H2: Hypotheses / Questions | I2: Risk metric Weightage (%) | J2: Standard initiative / value driver description | K2: 64 methods | L2: 16 Levers | M2: Low (1) | N2: Little (2) | O2: Middle (3) | P2: High (4) | Q2: Maturity score (1-4) | R2: Category health / maturity score (Value) | S2: Category health / maturity score (Risk) | T2: Weighted risk score calculation logic | U2: Weighted risk score (scale of 10) - higher score = higher risk | V2: Weighted category-level risk score | W2: Savings% (low) | X2: Savings% (high) | Y2: Addressability | Z2: Maturity adj savings % (low) | AA2: Maturity adj savings % (high) | AB2: Maturity adj savings $ (low) | AC2: Maturity adj savings $ (high) | AD2: # of value drivers / initiatives tested | AE2: Confidence score | AF2: Confidence bucket | AG2: Confidence adj savings % (low) | AH2: Confidence adj savings % (high) | AI2: Confidence adj savings $ (low) | AJ2: Confidence adj savings $ (high) | AK2: Savings BM% (low) | AL2: Savings BM% (high) | AM2: Intermediate calc. | AN2: Maturity adjusted savings weightage | AO2: savings % (low) | AP2: savings % (high) | AQ2: savings $ (low) | AR2: savings $ (high) | AS2: total proof points in methodology | AT2: Initiative impact score | AU2: Impact bucket | AV2: Proof points | AW2: Hypotheses brief | AX2: Qualifier type | AY2: Prompt to contextualize value driving Initiatives | AZ2: Proof point impact flag (GPT 5) | BA2: Prompt for overall initiative description | BB2: Risk levers linked to value levers/initiatives | BC2: Prompt to contextualize risk for value initiatives | BD2: Risk driver impact flag (GPT5) | BE2: Test 1 Proof point contextualization---- Perplexity (Claude Sonnet 4.0) | BF2: Test 2 Proof point contextualization---- ChatGPT (GPT 5) | BG2: Test 2 Proof point contextualization---- Perplexity (Claude Sonnet 4.0) | BH2: Test 2 Value contextualization ---- ChatGPT (GPT 5) applied on proof-point insights generated by Sonnet | BI2: Test 2 Risk contextualization for Value initiatives -- Perplexity (Sonnet 4.0) | BJ2: Test 2 - Final description of initiatives (Perplexity - Sonnrt 4.0) | BK2: Regional / country-specific cost differences | BL2: Fragmentation - by region | BM2: Fragmentation - by Supplier | BN2: Unit Price / index / cost driver trends | BO2: Internal price arbitrage | BP2: Category size vs peers | BQ2: Supplier concentration | BR2: Price volatility risk | BS2: Supplier conc risk | BT2: Supplier financial risk | BU2: Supplier geopolitical risk | BV2: Flag (active logics)
